{"uuid": "8934c910-6ccc-47a0-9ca1-4526a6bde13e", "children": ["e5711aa1-fe2d-448b-8e0a-a6909eb64ad2", "c20ce286-d4ea-41a8-9c7e-42f6cfe401bc", "a5a3c092-8ae0-45f8-acca-c81d94451e89", "916112c3-8c5a-4af6-a46e-4b3a2aa31fa8"], "befores": [{"name": "setup", "status": "broken", "statusDetails": {"message": "selenium.common.exceptions.WebDriverException: Message: Process unexpectedly closed with status 0\n\n", "trace": "  File \"X:\\Automation Testing\\03. Pytest Framework\\.venv1\\Lib\\site-packages\\pluggy\\_callers.py\", line 38, in run_old_style_hookwrapper\n    res = yield\n          ^^^^^\n  File \"X:\\Automation Testing\\03. Pytest Framework\\.venv1\\Lib\\site-packages\\pluggy\\_callers.py\", line 139, in _multicall\n    teardown.throw(exception)\n    ~~~~~~~~~~~~~~^^^^^^^^^^^\n  File \"X:\\Automation Testing\\03. Pytest Framework\\.venv1\\Lib\\site-packages\\_pytest\\setuponly.py\", line 36, in pytest_fixture_setup\n    return (yield)\n            ^^^^^\n  File \"X:\\Automation Testing\\03. Pytest Framework\\.venv1\\Lib\\site-packages\\pluggy\\_callers.py\", line 121, in _multicall\n    res = hook_impl.function(*args)\n  File \"X:\\Automation Testing\\03. Pytest Framework\\.venv1\\Lib\\site-packages\\_pytest\\fixtures.py\", line 1195, in pytest_fixture_setup\n    result = call_fixture_func(fixturefunc, request, kwargs)\n  File \"X:\\Automation Testing\\03. Pytest Framework\\.venv1\\Lib\\site-packages\\_pytest\\fixtures.py\", line 922, in call_fixture_func\n    fixture_result = next(generator)\n  File \"X:\\Automation Testing\\06. CredKart_Pytest_Revision\\testCases\\conftest.py\", line 29, in setup\n    driver = webdriver.Firefox()\n  File \"X:\\Automation Testing\\03. Pytest Framework\\.venv1\\Lib\\site-packages\\selenium\\webdriver\\firefox\\webdriver.py\", line 72, in __init__\n    super().__init__(command_executor=executor, options=options)\n    ~~~~~~~~~~~~~~~~^^^^^^^^^^^^^^^^^^^^^^^^^^^^^^^^^^^^^^^^^^^^\n  File \"X:\\Automation Testing\\03. Pytest Framework\\.venv1\\Lib\\site-packages\\selenium\\webdriver\\remote\\webdriver.py\", line 257, in __init__\n    self.start_session(capabilities)\n    ~~~~~~~~~~~~~~~~~~^^^^^^^^^^^^^^\n  File \"X:\\Automation Testing\\03. Pytest Framework\\.venv1\\Lib\\site-packages\\selenium\\webdriver\\remote\\webdriver.py\", line 356, in start_session\n    response = self.execute(Command.NEW_SESSION, caps)[\"value\"]\n               ~~~~~~~~~~~~^^^^^^^^^^^^^^^^^^^^^^^^^^^\n  File \"X:\\Automation Testing\\03. Pytest Framework\\.venv1\\Lib\\site-packages\\selenium\\webdriver\\remote\\webdriver.py\", line 447, in execute\n    self.error_handler.check_response(response)\n    ~~~~~~~~~~~~~~~~~~~~~~~~~~~~~~~~~^^^^^^^^^^\n  File \"X:\\Automation Testing\\03. Pytest Framework\\.venv1\\Lib\\site-packages\\selenium\\webdriver\\remote\\errorhandler.py\", line 232, in check_response\n    raise exception_class(message, screen, stacktrace)\n"}, "start": 1754977124976, "stop": 1754977134009}, {"name": "setup", "status": "broken", "statusDetails": {"message": "selenium.common.exceptions.TimeoutException: Message: Failed to read marionette port\n\n", "trace": "  File \"X:\\Automation Testing\\03. Pytest Framework\\.venv1\\Lib\\site-packages\\pluggy\\_callers.py\", line 38, in run_old_style_hookwrapper\n    res = yield\n          ^^^^^\n  File \"X:\\Automation Testing\\03. Pytest Framework\\.venv1\\Lib\\site-packages\\pluggy\\_callers.py\", line 139, in _multicall\n    teardown.throw(exception)\n    ~~~~~~~~~~~~~~^^^^^^^^^^^\n  File \"X:\\Automation Testing\\03. Pytest Framework\\.venv1\\Lib\\site-packages\\_pytest\\setuponly.py\", line 36, in pytest_fixture_setup\n    return (yield)\n            ^^^^^\n  File \"X:\\Automation Testing\\03. Pytest Framework\\.venv1\\Lib\\site-packages\\pluggy\\_callers.py\", line 121, in _multicall\n    res = hook_impl.function(*args)\n  File \"X:\\Automation Testing\\03. Pytest Framework\\.venv1\\Lib\\site-packages\\_pytest\\fixtures.py\", line 1195, in pytest_fixture_setup\n    result = call_fixture_func(fixturefunc, request, kwargs)\n  File \"X:\\Automation Testing\\03. Pytest Framework\\.venv1\\Lib\\site-packages\\_pytest\\fixtures.py\", line 922, in call_fixture_func\n    fixture_result = next(generator)\n  File \"X:\\Automation Testing\\06. CredKart_Pytest_Revision\\testCases\\conftest.py\", line 29, in setup\n    driver = webdriver.Firefox()\n  File \"X:\\Automation Testing\\03. Pytest Framework\\.venv1\\Lib\\site-packages\\selenium\\webdriver\\firefox\\webdriver.py\", line 72, in __init__\n    super().__init__(command_executor=executor, options=options)\n    ~~~~~~~~~~~~~~~~^^^^^^^^^^^^^^^^^^^^^^^^^^^^^^^^^^^^^^^^^^^^\n  File \"X:\\Automation Testing\\03. Pytest Framework\\.venv1\\Lib\\site-packages\\selenium\\webdriver\\remote\\webdriver.py\", line 257, in __init__\n    self.start_session(capabilities)\n    ~~~~~~~~~~~~~~~~~~^^^^^^^^^^^^^^\n  File \"X:\\Automation Testing\\03. Pytest Framework\\.venv1\\Lib\\site-packages\\selenium\\webdriver\\remote\\webdriver.py\", line 356, in start_session\n    response = self.execute(Command.NEW_SESSION, caps)[\"value\"]\n               ~~~~~~~~~~~~^^^^^^^^^^^^^^^^^^^^^^^^^^^\n  File \"X:\\Automation Testing\\03. Pytest Framework\\.venv1\\Lib\\site-packages\\selenium\\webdriver\\remote\\webdriver.py\", line 447, in execute\n    self.error_handler.check_response(response)\n    ~~~~~~~~~~~~~~~~~~~~~~~~~~~~~~~~~^^^^^^^^^^\n  File \"X:\\Automation Testing\\03. Pytest Framework\\.venv1\\Lib\\site-packages\\selenium\\webdriver\\remote\\errorhandler.py\", line 232, in check_response\n    raise exception_class(message, screen, stacktrace)\n"}, "start": 1754977134148, "stop": 1754977231241}, {"name": "setup", "status": "passed", "start": 1754977231919, "stop": 1754977239934}], "afters": [{"name": "setup::0", "status": "passed", "start": 1754977254047, "stop": 1754977258452}], "start": 1754977231919, "stop": 1754977258452}